Workbook

Sheet balancing
B1: Total AC Body+Headgear per tier
B2: Plate | C2: Mail | D2: Leather | E2: Cloth
A3: T1 | C3: =SUM('equipment-armor'!G24,'equipment-armor'!G30) -> 12 | D3: =SUM('equipment-armor'!G14,'equipment-armor'!G19) -> 9 | E3: =SUM('equipment-armor'!G2,'equipment-armor'!G8) -> 5
A4: T2 | B4: =SUM('equipment-armor'!G35,'equipment-armor'!G40) -> 19 | C4: =SUM('equipment-armor'!G25,'equipment-armor'!G31) -> 28 | D4: =SUM('equipment-armor'!G15,'equipment-armor'!G20) -> 12 | E4: =SUM('equipment-armor'!G3,'equipment-armor'!G9) -> 9
A5: T3 | B5: =SUM('equipment-armor'!G36,'equipment-armor'!G41) -> 32 | C5: =SUM('equipment-armor'!G26,'equipment-armor'!G32) -> 35 | D5: =SUM('equipment-armor'!G16,'equipment-armor'!G21) -> 20 | E5: =SUM('equipment-armor'!G4,'equipment-armor'!G10) -> 14
A6: T4 | B6: =SUM('equipment-armor'!G37,'equipment-armor'!G42) -> 43 | C6: =SUM('equipment-armor'!G27,'equipment-armor'!G33) -> 43 | D6: =SUM('equipment-armor'!G17,'equipment-armor'!G22) -> 33 | E6: =SUM('equipment-armor'!G5,'equipment-armor'!G11) -> 13
A7: T5 | B7: =SUM('equipment-armor'!G38,'equipment-armor'!G43) -> 52 | C7: =SUM('equipment-armor'!G28,'equipment-armor'!G33) -> 44 | D7: =SUM('equipment-armor'!G18,'equipment-armor'!G23) -> 0 | E7: =SUM('equipment-armor'!G6,'equipment-armor'!G12) -> 34
A9: Ac Modifier | B9: 2.5
A10: Level Attribute Mod | B10: 20
A12: Shields | B12: Average | F12: Average Hit | G12: Plate | H12: Mail | I12: Leather | J12: Cloth
A13: ='equipment-shields'!F2 -> 2 | F13: 5 | H13: =DAMAGEAFTERAC(F13,C3, ArmorClassModifier) -> 2 | I13: =DAMAGEAFTERAC(F13,D3, ArmorClassModifier) -> 2 | J13: =DAMAGEAFTERAC(F13,E3, ArmorClassModifier) -> 3
A14: ='equipment-shields'!F3 -> 5 | B14: 4 | F14: 10 | G14: =DAMAGEAFTERAC(F14,B4, ArmorClassModifier) -> 5 | H14: =DAMAGEAFTERAC(F14,C4, ArmorClassModifier) -> 4 | I14: =DAMAGEAFTERAC(F14,D4, ArmorClassModifier) -> 6 | J14: =DAMAGEAFTERAC(F14,E4, ArmorClassModifier) -> 7
A15: ='equipment-shields'!F4 -> 14 | F15: 18 | G15: =DAMAGEAFTERAC(F15,B5, ArmorClassModifier) -> 10 | H15: =DAMAGEAFTERAC(F15,C5, ArmorClassModifier) -> 10 | I15: =DAMAGEAFTERAC(F15,D5, ArmorClassModifier) -> 12 | J15: =DAMAGEAFTERAC(F15,E5, ArmorClassModifier) -> 13
A16: ='equipment-shields'!F5 -> 13 | B16: 14 | F16: 30 | G16: =DAMAGEAFTERAC(F16,B6, ArmorClassModifier) -> 19 | I16: =DAMAGEAFTERAC(F16,D6, ArmorClassModifier) -> 20 | J16: =DAMAGEAFTERAC(F16,E6, ArmorClassModifier) -> 25
A17: ='equipment-shields'!F6 -> 19 | F17: 50 | G17: =DAMAGEAFTERAC(F17,B7, ArmorClassModifier ) -> 35 | H17: =DAMAGEAFTERAC(F17,C7, ArmorClassModifier) -> 36 | J17: =DAMAGEAFTERAC(F17,E7, ArmorClassModifier) -> 39
A18: ='equipment-shields'!F7 -> 18 | B18: 18
A19: ='equipment-shields'!F8 -> 15 | G19: With Shield
A20: ='equipment-shields'!F9 -> 23 | B20: 21 | F20: Average Hit | G20: Plate | H20: Mail | I20: Leather | J20: Cloth
A21: ='equipment-shields'!F10 -> 28 | F21: 5 | H21: =DAMAGEAFTERAC(F21,C3+$B$14, ArmorClassModifier) -> 2 | I21: =DAMAGEAFTERAC(F21,D3+$B$14, ArmorClassModifier) -> 2 | J21: =DAMAGEAFTERAC(F21,E3+$B$14, ArmorClassModifier) -> 2
A22: ='equipment-shields'!F11 -> 24 | F22: 10 | G22: =DAMAGEAFTERAC(F22,B4+$B$16, ArmorClassModifier) -> 4 | H22: =DAMAGEAFTERAC(F22,C4+$B$16, ArmorClassModifier) -> 3 | I22: =DAMAGEAFTERAC(F22,D4+$B$16, ArmorClassModifier) -> 4 | J22: =DAMAGEAFTERAC(F22,E4+$B$16, ArmorClassModifier) -> 5
A23: ='equipment-shields'!F12 -> 28 | B23: 26 | F23: 18 | G23: =DAMAGEAFTERAC(F23,B5+$B$18, ArmorClassModifier) -> 8 | H23: =DAMAGEAFTERAC(F23,C5+$B$18, ArmorClassModifier) -> 8 | I23: =DAMAGEAFTERAC(F23,D5+$B$18, ArmorClassModifier) -> 9 | J23: =DAMAGEAFTERAC(F23,E5+$B$18, ArmorClassModifier) -> 10
F24: 30 | G24: =DAMAGEAFTERAC(F24,B6+$B$20, ArmorClassModifier) -> 16 | H24: =DAMAGEAFTERAC(F24,C6+$B$20, ArmorClassModifier) -> 16 | I24: =DAMAGEAFTERAC(F24,D6+$B$20, ArmorClassModifier) -> 17 | J24: =DAMAGEAFTERAC(F24,E6+$B$20, ArmorClassModifier) -> 20
F25: 50 | G25: =DAMAGEAFTERAC(F25,B7+$B$23, ArmorClassModifier) -> 30 | H25: =DAMAGEAFTERAC(F25,C7+$B$23, ArmorClassModifier) -> 32 | J25: =DAMAGEAFTERAC(F25,E7+$B$23, ArmorClassModifier) -> 33
A28: Gear slot count | B28: 7
A29: Max attribute per slot | B29: 20
A30: Derived attribute mod | B30: 2.5
A31: Max derived per slot | B31: =B29*B30 -> 50
A32: Discretionary per main lvl | B32: 5
A33: Max Level Main | B33: 10
A34: Discretionary main total | B34: =(B33-1)*B32 -> 45
A35: Max level Sub | B35: =B33/2 -> 5
A36: Discretionary per sub lvl | B36: 2
A37: Discretionary sub total | B37: =B36*B35 -> 10
A38: Discretionary total | B38: =B37+B34 -> 55
A39: Max attributes gear | B39: =B29*B28 -> 140
A40: Max inherent single | B40: =#REF! -> #REF!
A41: Single attribute max | B41: =B39+B38+B40 -> #REF!
A42: Believable percent allocated to single attribute | B42: 0.35
A43: Avg high attribute alloc | B43: =B42*B41 -> #REF!

Sheet equipment-requirement-targets
A1: baseItem | B1: equipmentType | C1: study | D1: goal | E1: attributes | F1: weaponSpecialty | G1: mainClass | H1: supportClass | I1: availabilityPercentile
A2: Rags | B2: BodyArmor
A3: Cloak | B3: BodyArmor | C3: CasterDamageMixed | D3: IceBoltDamage | E3: Spirit | F3: Shields | G3: Mage | H3: Rogue | I3: 0.5
A4: Robe | B4: BodyArmor | C4: CasterDamageMixed | D4: IceBoltDamage | E4: Spirit | F4: Shields | G4: Mage | H4: Rogue | I4: 0.5
A5: OfficersRobe | B5: BodyArmor | C5: CasterDamageMixed | D5: IceBoltDamage | E5: Spirit | F5: Shields | G5: Mage | H5: Rogue | I5: 0.5
A6: MageRobe | B6: BodyArmor | C6: CasterDamageMixed | D6: IceBoltDamage | E6: Spirit | F6: Shields | G6: Mage | H6: Rogue | I6: 0.5
A8: Cap | B8: HeadGear
A9: Bandana | B9: HeadGear | C9: CasterDamageMixed | D9: IceBoltDamage | E9: Spirit | F9: Shields | G9: Mage | H9: Rogue | I9: 0.5
A10: PaddedCap | B10: HeadGear | C10: CasterDamageMixed | D10: IceBoltDamage | E10: Spirit | F10: Shields | G10: Mage | H10: Rogue | I10: 0.5
A11: Ribbon | B11: HeadGear | C11: CasterDamageMixed | D11: IceBoltDamage | E11: Spirit | F11: Shields | G11: Mage | H11: Rogue | I11: 0.5
A12: WizardHat | B12: HeadGear | C12: CasterDamageMixed | D12: IceBoltDamage | E12: Spirit | F12: Shields | G12: Mage | H12: Rogue | I12: 0.66
A14: LeatherVest | B14: BodyArmor | C14: AttackDamageGroupOne | D14: WeaponAttackDamage | E14: Dexterity | F14: TwoHandedRanged | G14: Rogue | H14: Warrior | I14: 0.5
A15: HardLeather | B15: BodyArmor | C15: AttackDamageGroupOne | D15: WeaponAttackDamage | E15: Dexterity | F15: TwoHandedRanged | G15: Rogue | H15: Warrior | I15: 0.4
A16: StuddedLeather | B16: BodyArmor | C16: AttackDamageGroupOne | D16: WeaponAttackDamage | E16: Dexterity | F16: TwoHandedRanged | G16: Rogue | H16: Warrior | I16: 0.5
A17: DemonsaurLeather | B17: BodyArmor | C17: AttackDamageGroupOne | D17: WeaponAttackDamage | E17: Dexterity | F17: TwoHandedRanged | G17: Rogue | H17: Warrior | I17: 0.5
A19: Eyepatch | B19: HeadGear | C19: AttackDamageGroupOne | D19: WeaponAttackDamage | E19: Dexterity | F19: TwoHandedRanged | G19: Rogue | H19: Warrior | I19: 0
A20: LeatherHat | B20: HeadGear | C20: AttackDamageGroupOne | D20: WeaponAttackDamage | E20: Dexterity | F20: TwoHandedRanged | G20: Rogue | H20: Warrior | I20: 0.33
A21: LeatherHelm | B21: HeadGear | C21: AttackDamageGroupOne | D21: WeaponAttackDamage | E21: Dexterity | F21: TwoHandedRanged | G21: Rogue | H21: Warrior | I21: 0.5
A22: DemonsaurHelm | B22: HeadGear | C22: AttackDamageGroupOne | D22: WeaponAttackDamage | E22: Dexterity | F22: TwoHandedRanged | G22: Rogue | H22: Warrior | I22: 0.5
... A31: OhmushellMail | B31: BodyArmor | C31: AttackDamageGroupOne | D31: WeaponAttackDamage | E31: Dexterity, Strength | F31: Shields | G31: Mage | H31: Rogue | I31: 0.5
A33: Hairpin | B33: HeadGear
A34: Skullcap | B34: HeadGear | C34: AttackDamageGroupOne | D34: WeaponAttackDamage | E34: Dexterity, Strength | F34: Shields | G34: Mage | H34: Rogue | I34: 0.33
A35: Coif | B35: HeadGear | C35: CasterDamageMixed | D35: IceBoltDamage | E35: Spirit | F35: Shields | G35: Mage | H35: Rogue | I35: 0.25
A36: Coif | B36: HeadGear | C36: AttackDamageGroupOne | D36: WeaponAttackDamage | E36: Dexterity, Strength | F36: Shields | G36: Mage | H36: Rogue | I36: 0.5
A37: OhmushellMask | B37: HeadGear | C37: AttackDamageGroupOne | D37: WeaponAttackDamage | E37: Dexterity, Strength | F37: Shields | G37: Mage | H37: Rogue | I37: 0.5
A39: BreastPlate | B39: BodyArmor | C39: AttackDamageGroupOne | D39: WeaponAttackDamage | E39: Strength | F39: TwoHandedMelee | G39: Warrior | H39: Rogue | I39: 0.66
A40: FieldPlate | B40: BodyArmor | C40: AttackDamageGroupOne | D40: WeaponAttackDamage | E40: Strength | F40: TwoHandedMelee | G40: Warrior | H40: Rogue | I40: 0.5
A41: GothicPlate | B41: BodyArmor | C41: AttackDamageGroupOne | D41: WeaponAttackDamage | E41: Strength | F41: TwoHandedMelee | G41: Warrior | H41: Rogue | I41: 0.75
A42: FullPlate | B42: BodyArmor | C42: AttackDamageGroupOne | D42: WeaponAttackDamage | E42: Strength | F42: TwoHandedMelee | G42: Warrior | H42: Rogue | I42: 0.75
A44: Circlet | B44: HeadGear | C44: AttackDamageGroupOne | D44: WeaponAttackDamage | E44: Strength | F44: TwoHandedMelee | G44: Warrior | H44: Rogue | I44: 0
A45: Crown | B45: HeadGear | C45: AttackDamageGroupOne | D45: WeaponAttackDamage | E45: Strength | F45: TwoHandedMelee | G45: Warrior | H45: Rogue | I45: 0.5
A46: FullHelm | B46: HeadGear | C46: AttackDamageGroupOne | D46: WeaponAttackDamage | E46: Strength | F46: TwoHandedMelee | G46: Warrior | H46: Rogue | I46: 0.75
A47: GreatHelm | B47: HeadGear | C47: AttackDamageGroupOne | D47: WeaponAttackDamage | E47: Strength | F47: TwoHandedMelee | G47: Warrior | H47: Rogue | I47: 0.75
A49: Stick | B49: OneHandedMeleeWeapon
A50: Club | B50: OneHandedMeleeWeapon | C50: CasterDualWieldRanged | D50: WeaponAttackDamage | E50: Strength | F50: DualWield | G50: Warrior | H50: Rogue | I50: 0.1
A51: Mace | B51: OneHandedMeleeWeapon | C51: CasterDualWieldRanged | D51: WeaponAttackDamage | E51: Strength | F51: DualWield | G51: Warrior | H51: Rogue | I51: 0.33
A52: Morningstar | B52: OneHandedMeleeWeapon | C52: CasterDualWieldRanged | D52: WeaponAttackDamage | E52: Strength | F52: DualWield | G52: Warrior | H52: Rogue | I52: 0.33
A53: WarHammer | B53: OneHandedMeleeWeapon | C53: CasterDualWieldRanged | D53: WeaponAttackDamage | E53: Strength | F53: DualWield | G53: Warrior | H53: Rogue | I53: 0.33
A55: ButterKnife | B55: OneHandedMeleeWeapon
A56: ShortSword | B56: OneHandedMeleeWeapon | C56: CasterDualWieldRanged | D56: WeaponAttackDamage | E56: Strength, Dexterity | F56: DualWield | G56: Warrior | H56: Rogue | I56: 0.2
...

Sheet equipment-armor
A1: baseItem | B1: equipmentType | C1: affixProfile | D1: minLvl | E1: maxLvl | F1: minAc | G1: maxAc | H1: armorCategory | I1: maxDura | J1: reqStr | K1: reqDex | L1: reqSpr | M1: reqVit | N1: reqAgi
A2: Rags | B2: BodyArmor | C2: BodyArmorCloth | D2: 1 | E2: 3 | F2: 1 | G2: 3 | H2: Cloth | I2: 12
A3: Cloak | B3: BodyArmor | C3: BodyArmorCloth | D3: 2 | E3: 4 | F3: 2 | G3: 5 | H3: Cloth | I3: 14
A4: Robe | B4: BodyArmor | C4: BodyArmorCloth | D4: 3 | E4: 7 | F4: 4 | G4: 8 | H4: Cloth | I4: 20
A5: OfficersRobe | B5: BodyArmor | C5: BodyArmorCloth | D5: 6 | E5: 9 | F5: 8 | G5: 12 | H5: Cloth | I5: 22
A6: MageRobe | B6: BodyArmor | C6: BodyArmorCloth | D6: 8 | E6: 10 | F6: 12 | G6: 20 | H6: Cloth | I6: 28
A8: Cap | B8: HeadGear | C8: HeadGearCloth | D8: 1 | E8: 3 | F8: 1 | G8: 2 | H8: Cloth | I8: 12
A9: Bandana | B9: HeadGear | C9: HeadGearCloth | D9: 2 | E9: 4 | F9: 2 | G9: 4 | H9: Cloth | I9: 14
A10: PaddedCap | B10: HeadGear | C10: HeadGearCloth | D10: 3 | E10: 6 | F10: 3 | G10: 6 | H10: Cloth | I10: 14
A11: Ribbon | B11: HeadGear | C11: HeadGearCloth | D11: 5 | E11: 10 | F11: 1 | G11: 1 | H11: Cloth | I11: 8
A12: WizardHat | B12: HeadGear | C12: HeadGearCloth | D12: 7 | E12: 10 | F12: 6 | G12: 14 | H12: Cloth | I12: 20
A14: LeatherVest | B14: BodyArmor | C14: BodyArmorLeather | D14: 3 | E14: 5 | F14: 2 | G14: 5 | H14: Leather | I14: 16
A15: HardLeather | B15: BodyArmor | C15: BodyArmorLeather | D15: 5 | E15: 7 | F15: 4 | G15: 7 | H15: Leather | I15: 18
... A43: GreatHelm | B43: HeadGear | C43: HeadGearPlate | D43: 9 | E43: 10 | F43: 18 | G43: 22 | H43: Plate | I43: 50

Sheet equipment-weapons
A1: baseItem | B1: equipmentType | C1: affixProfile | D1: minLvl | E1: maxLvl | F1: minDmg | G1: maxDmg | H1: damageClassificationsCount | I1: damageClassifications | J1: maxDura | K1: reqStr | L1: reqDex | M1: reqSpr | N1: reqVit | O1: reqAgi
A2: Stick | B2: OneHandedMeleeWeapon | C2: OneHandedMelee | D2: 0 | E2: 0 | F2: 1 | G2: 3 | H2: 1 | I2: Physical:Blunt | J2: 8
A3: Club | B3: OneHandedMeleeWeapon | C3: OneHandedMelee | D3: 1 | E3: 3 | F3: 1 | G3: 4 | H3: 1 | I3: Physical:Blunt | J3: 14 | K3: 0
A4: Mace | B4: OneHandedMeleeWeapon | C4: OneHandedMelee | D4: 2 | E4: 5 | F4: 1 | G4: 8 | H4: 1 | I4: Physical:Blunt | J4: 22
A5: Morningstar | B5: OneHandedMeleeWeapon | C5: OneHandedMelee | D5: 4 | E5: 8 | F5: 2 | G5: 12 | H5: 1 | I5: Physical:Blunt | J5: 18
A6: WarHammer | B6: OneHandedMeleeWeapon | C6: OneHandedMelee | D6: 8 | E6: 10 | F6: 4 | G6: 16 | H6: 1 | I6: Physical:Blunt | J6: 20
A7: ButterKnife | B7: OneHandedMeleeWeapon | C7: OneHandedMelee | D7: 0 | E7: 0 | F7: 1 | G7: 2 | H7: 1 | I7: Physical:Slashing | J7: 7
A8: ShortSword | B8: OneHandedMeleeWeapon | C8: OneHandedMelee | D8: 2 | E8: 4 | F8: 2 | G8: 6 | H8: 1 | I8: Physical:Slashing | J8: 15 | K8: 1 | L8: 1
A9: Blade | B9: OneHandedMeleeWeapon | C9: OneHandedMelee | D9: 3 | E9: 5 | F9: 4 | G9: 8 | H9: 1 | I9: Physical:Slashing | J9: 17
A10: BroadSword | B10: OneHandedMeleeWeapon | C10: OneHandedMelee | D10: 6 | E10: 8 | F10: 4 | G10: 12 | H10: 1 | I10: Physical:Slashing | J10: 24
A11: BastardSword | B11: OneHandedMeleeWeapon | C11: OneHandedMelee | D11: 8 | E11: 10 | F11: 6 | G11: 15 | H11: 2 | I11: Physical:Slashing|Physical:Piercing | J11: 25
A12: Dagger | B12: OneHandedMeleeWeapon | C12: OneHandedMelee | D12: 1 | E12: 3 | F12: 1 | G12: 4 | H12: 2 | I12: Physical:Slashing|Physical:Piercing | J12: 9 | K12: 1 | L12: 1
A13: Rapier | B13: OneHandedMeleeWeapon | C13: OneHandedMelee | D13: 3 | E13: 6 | F13: 1 | G13: 11 | H13: 1 | I13: Physical:Piercing | J13: 13
A14: ShortSpear | B14: OneHandedMeleeWeapon | C14: OneHandedMelee | D14: 6 | E14: 9 | F14: 4 | G14: 13 | H14: 1 | I14: Physical:Piercing | J14: 25
A15: RuneSword | B15: OneHandedMeleeWeapon | C15: OneHandedMelee | D15: 5 | E15: 10 | F15: 2 | G15: 12 | H15: 2 | I15: Physical:Slashing:Fire|Physical:Slashing:Ice|Physical:Slashing:Lightning|Physical:Slashing:Water|Physical:Slashing:Earth|Physical:Slashing:Wind | J15: 20
A16: EtherBlade | B16: OneHandedMeleeWeapon | C16: OneHandedMelee | D16: 5 | E16: 8 | F16: 6 | G16: 10 | H16: 1 | I16: Magical:Slashing | J16: 12
A17: IceBlade | B17: OneHandedMeleeWeapon | C17: OneHandedMelee | D17: 2 | E17: 4 | F17: 2 | G17: 6 | H17: 1 | I17: Physical:Slashing:Ice | J17: 9
A18: MapleWand | B18: OneHandedMeleeWeapon | C18: OneHandedMelee | D18: 2 | E18: 4 | F18: 1 | G18: 8 | H18: 1 | I18: Magical | J18: 10
A19: WillowWand | B19: OneHandedMeleeWeapon | C19: OneHandedMelee | D19: 3 | E19: 6 | F19: 2 | G19: 10 | H19: 1 | I19: Magical | J19: 14
A20: YewWand | B20: OneHandedMeleeWeapon | C20: OneHandedMelee | D20: 5 | E20: 7 | F20: 3 | G20: 13 | H20: 1 | I20: Magical | J20: 18
A21: RoseWand | B21: OneHandedMeleeWeapon | C21: OneHandedMelee | D21: 8 | E21: 10 | F21: 6 | G21: 16 | H21: 1 | I21: Magical | J21: 24
A22: RottingBranch | B22: TwoHandedMeleeWeapon | C22: TwoHandedMelee | D22: 0 | E22: 0 | F22: 1 | G22: 7 | H22: 1 | I22: Physical:Blunt | J22: 6
A23: BoStaff | B23: TwoHandedMeleeWeapon | C23: TwoHandedMelee | D23: 1 | E23: 3 | F23: 2 | G23: 8 | H23: 1 | I23: Physical:Blunt | J23: 8 | K23: 0
A24: Spear | B24: TwoHandedMeleeWeapon | C24: TwoHandedMelee | D24: 2 | E24: 4 | F24: 3 | G24: 9 | H24: 1 | I24: Physical:Piercing | J24: 11
A25: Bardiche | B25: TwoHandedMeleeWeapon | C25: TwoHandedMelee | D25: 2 | E25: 4 | F25: 1 | G25: 11 | H25: 1 | I25: Physical:Slashing | J25: 15
A26: SplittingMaul | B26: TwoHandedMeleeWeapon | C26: TwoHandedMelee | D26: 4 | E26: 6 | F26: 6 | G26: 12 | H26: 2 | I26: Physical:Slashing|Physical:Blunt | J26: 16
A27: Maul | B27: TwoHandedMeleeWeapon | C27: TwoHandedMelee | D27: 5 | E27: 7 | F27: 9 | G27: 14 | H27: 1 | I27: Physical:Blunt | J27: 18
A28: BattleAxe | B28: TwoHandedMeleeWeapon | C28: TwoHandedMelee | D28: 5 | E28: 7 | F28: 6 | G28: 15 | H28: 1 | I28: Physical:Slashing | J28: 21
A29: Glaive | B29: TwoHandedMeleeWeapon | C29: TwoHandedMelee | D29: 6 | E29: 8 | F29: 8 | G29: 17 | H29: 2 | I29: Physical:Slashing|Physical:Piercing | J29: 19
A30: ElementalStaff | B30: TwoHandedMeleeWeapon | C30: TwoHandedMelee | D30: 7 | E30: 9 | F30: 10 | G30: 18 | H30: 2 | I30: Physical:Blunt:Fire|Physical:Blunt:Ice|Physical:Blunt:Lightning|Physical:Blunt:Water|Physical:Blunt:Earth|Physical:Blunt:Wind | J30: 18
A31: Trident | B31: TwoHandedMeleeWeapon | C31: TwoHandedMelee | D31: 8 | E31: 10 | F31: 14 | G31: 26 | H31: 2 | I31: Magical:none:Water|Physical:Piercing | J31: 23
A32: GreatAxe | B32: TwoHandedMeleeWeapon | C32: TwoHandedMelee | D32: 9 | E32: 10 | F32: 15 | G32: 35 | H32: 1 | I32: Physical:Slashing | J32: 28
A33: GravityHammer | B33: TwoHandedMeleeWeapon | C33: TwoHandedMelee | D33: 9 | E33: 10 | F33: 20 | G33: 30 | H33: 1 | I33: Physical:Blunt | J33: 40
A34: ElmStaff | B34: TwoHandedMeleeWeapon | C34: TwoHandedMeleeCaster | D34: 3 | E34: 6 | F34: 4 | G34: 12 | H34: 1 | I34: Physical:Blunt | J34: 16
A35: MahoganyStaff | B35: TwoHandedMeleeWeapon | C35: TwoHandedMeleeCaster | D35: 5 | E35: 8 | F35: 8 | G35: 22 | H35: 1 | I35: Physical:Blunt | J35: 19
A36: EbonyStaff | B36: TwoHandedMeleeWeapon | C36: TwoHandedMeleeCaster | D36: 8 | E36: 10 | F36: 10 | G36: 32 | H36: 1 | I36: Physical:Blunt | J36: 24
A37: ShortBow | B37: TwoHandedRangedWeapon | C37: TwoHandedRanged | D37: 1 | E37: 3 | F37: 2 | G37: 7 | H37: 1 | I37: Physical:Piercing | J37: 15 | L37: 2
A38: RecurveBow | B38: TwoHandedRangedWeapon | C38: TwoHandedRanged | D38: 3 | E38: 5 | F38: 5 | G38: 10 | H38: 1 | I38: Physical:Piercing | J38: 16
A39: CompositeBow | B39: TwoHandedRangedWeapon | C39: TwoHandedRanged | D39: 5 | E39: 8 | F39: 8 | G39: 16 | H39: 1 | I39: Physical:Piercing | J39: 26
A40: MilitaryBow | B40: TwoHandedRangedWeapon | C40: TwoHandedRanged | D40: 8 | E40: 10 | F40: 12 | G40: 26 | H40: 1 | I40: Physical:Piercing | J40: 25
...

Sheet equipment-shields
A1: baseItem | B1: affixProfile | C1: minLvl | D1: maxLvl | E1: minAc | F1: maxAc | G1: shieldSize | H1: maxDura | I1: reqStr | J1: reqDex | K1: reqSpr | L1: reqVit | M1: reqAgi
A2: PotLid | B2: Shield | C2: 0 | D2: 0 | E2: 2 | F2: 2 | G2: Small | H2: 8
A3: CabinetDoor | B3: Shield | C3: 1 | D3: 3 | E3: 3 | F3: 5 | G3: Small | H3: 16 | I3: 0
A4: Heater | B4: Shield | C4: 2 | D4: 4 | E4: 10 | F4: 14 | G4: Medium | H4: 22
A5: Buckler | B5: Shield | C5: 3 | D5: 5 | E5: 9 | F5: 13 | G5: Small | H5: 18
A6: Pavise | B6: Shield | C6: 4 | D6: 6 | E6: 16 | F6: 19 | G6: Large | H6: 20
A7: Aspis | B7: Shield | C7: 5 | D7: 7 | E7: 15 | F7: 18 | G7: Medium | H7: 18
A8: LanternShield | B8: Shield | C8: 5 | D8: 6 | E8: 13 | F8: 15 | G8: Small | H8: 15
A9: KiteShield | B9: Shield | C9: 6 | D9: 8 | E9: 19 | F9: 23 | G9: Medium | H9: 24
A10: TowerShield | B10: Shield | C10: 7 | D10: 10 | E10: 21 | F10: 28 | G10: Large | H10: 25
A11: AncientBuckler | B11: Shield | C11: 8 | D11: 10 | E11: 21 | F11: 24 | G11: Small | H11: 28
A12: GothicShield | B12: Shield | C12: 8 | D12: 10 | E12: 25 | F12: 28 | G12: Medium | H12: 28

Sheet equipment-jewelry
A1: baseItem | B1: equipmentType | C1: affixProfile | D1: minLvl | E1: maxLvl | F1: maxDura | G1: reqStr | H1: reqDex | I1: reqSpr | J1: reqVit | K1: reqAgi
A2: Ring | B2: Ring | C2: Jewelry | D2: 3 | E2: 10
A3: Amulet | B3: Amulet | C3: Jewelry | D3: 3 | E3: 10

Sheet equipment-affix-profiles
A1: affixProfile | B1: Prefix:Mp | C1: Prefix:FlatArmorClass | D1: Prefix:Accuracy | E1: Prefix:PercentDamage | F1: Prefix:LifeSteal | G1: Prefix:Evasion | H1: Prefix:ArmorPenetration | I1: Prefix:Agility | J1: Suffix:Strength | K1: Suffix:Spirit | L1: Suffix:Dexterity | M1: Suffix:Vitality | N1: Suffix:Hp | O1: Suffix:FlatDamage | P1: Suffix:Durability | Q1: Suffix:PercentArmorClass
A2: OneHandedMelee | D2: 5 | E2: 5 | F2: 5 | H2: 5 | I2: 5 | J2: 5 | K2: 5 | L2: 5 | O2: 5 | P2: 5
A3: TwoHandedMelee | D3: 5 | E3: 5 | F3: 5 | H3: 5 | I3: 5 | J3: 5 | K3: 5 | L3: 5 | M3: 5 | O3: 5 | P3: 5
A4: TwoHandedMeleeCaster | B4: 5 | F4: 5 | I4: 5 | K4: 5 | M4: 5 | P4: 5
A5: TwoHandedRanged | D5: 5 | E5: 5 | F5: 5 | G5: 5 | H5: 5 | I5: 5 | J5: 5 | K5: 5 | L5: 5 | M5: 5 | O5: 5 | P5: 5
A6: BodyArmorCloth | B6: 5 | C6: 5 | G6: 3 | I6: 3 | J6: 5 | K6: 5 | L6: 3 | M6: 5 | N6: 5 | P6: 5 | Q6: 5
A7: BodyArmorLeather | B7: 3 | C7: 5 | G7: 5 | I7: 5 | J7: 5 | K7: 3 | L7: 5 | M7: 5 | N7: 5 | P7: 5 | Q7: 5
A8: BodyArmorMail | B8: 5 | C8: 5 | G8: 5 | I8: 5 | J8: 5 | K8: 5 | L8: 5 | M8: 5 | N8: 5 | P8: 5 | Q8: 5
A9: BodyArmorPlate | B9: 3 | C9: 5 | J9: 5 | K9: 3 | L9: 3 | M9: 5 | N9: 5 | P9: 5 | Q9: 5
A10: HeadGearCloth | B10: 5 | C10: 5 | G10: 3 | I10: 3 | J10: 5 | K10: 5 | L10: 3 | M10: 5 | N10: 5 | P10: 5 | Q10: 5
A11: HeadGearLeather | B11: 3 | C11: 5 | D11: 5 | G11: 5 | I11: 5 | J11: 5 | K11: 3 | L11: 5 | M11: 5 | N11: 5 | P11: 5 | Q11: 5
A12: HeadGearMail | B12: 5 | C12: 5 | F12: 5 | G12: 5 | I12: 5 | J12: 5 | K12: 5 | L12: 5 | M12: 5 | N12: 5 | P12: 5 | Q12: 5
A13: HeadGearPlate | B13: 3 | C13: 5 | H13: 5 | J13: 5 | K13: 3 | L13: 3 | M13: 5 | N13: 5 | P13: 5 | Q13: 5
A14: Shield | B14: 5 | C14: 5 | G14: 5 | I14: 3 | J14: 5 | K14: 5 | L14: 5 | M14: 5 | N14: 5 | P14: 5 | Q14: 5
A15: Jewelry | B15: 5 | D15: 5 | F15: 5 | G15: 5 | H15: 5 | I15: 5 | J15: 5 | K15: 5 | L15: 5 | M15: 5 | N15: 5 | O15: 5

Sheet equipment-affix-overrides
A1: baseItem | B1: affixType | C1: maxTier
A2: LanternShield | B2: FlatDamage | C2: 5

Sheet class-starting-attributes
A1: combatantClass | B1: Strength | C1: Dexterity | D1: Spirit | E1: Vitality | F1: Agility | G1: Speed | H1: ArmorClass | I1: ArmorPenetration | J1: Accuracy | K1: Evasion | L1: Hp | M1: Mp
A2: Warrior | G2: 1 | J2: 80 | L2: 20 | M2: 2
A3: Rogue | G3: 1 | J3: 90 | L3: 18 | M3: 3
A4: Mage | G4: 1 | J4: 78 | L4: 15 | M4: 4

Sheet class-attributes-per-level
A1: combatantClass | B1: Strength | C1: Dexterity | D1: Spirit | E1: Vitality | F1: Agility | G1: Speed | H1: ArmorClass | I1: ArmorPenetration | J1: Accuracy | K1: Evasion | L1: Hp | M1: Mp
A2: Warrior | B2: 2.5 | C2: 1.5 | D2: 0.5 | E2: 1.75 | F2: 0.75 | L2: 2 | M2: 1
A3: Rogue | B3: 1.25 | C3: 2.5 | D3: 0.75 | E3: 1 | F3: 1.5 | L3: 1.5 | M3: 1.5
A4: Mage | B4: 1 | C4: 1.75 | D4: 2.5 | E4: 1 | F4: 0.75 | L4: 1 | M4: 2

Sheet monster-starting-attributes
A1: monsterType | B1: Strength | C1: Dexterity | D1: Spirit | E1: Vitality | F1: Agility | G1: Speed | H1: ArmorClass | I1: ArmorPenetration | J1: Accuracy | K1: Evasion | L1: Hp | M1: Mp
A2: Wolf | B2: 100 | E2: 1 | G2: 2 | H2: 0 | J2: 70 | L2: 4
A3: FireMage | D3: 4 | E3: 1.5 | G3: 1 | J3: 60 | L3: 3
A4: Cultist | B4: 20 | C4: 20 | D4: 6 | G4: 5 | J4: 0 | K4: 0 | L4: 40
A5: MantaRay | D5: 8 | E5: 1 | G5: 1 | J5: 100 | L5: 1
A6: Net | G6: 10 | L6: 3
A7: Spider | B7: 2 | C7: 7 | E7: 1.5 | F7: 2 | G7: 2 | J7: 80 | L7: 35 | M7: 2
A8: Slime | B8: 2 | C8: 4 | D8: 0 | E8: 1.5 | F8: 0 | G8: 1 | J8: 80 | L8: 5 | M8: 0
A9: Zombie | B9: 50 | E9: 0 | G9: 1 | H9: 0 | J9: 55 | L9: 7
A10: SkeletonWarrior | B10: 2 | E10: 2 | G10: 1 | H10: 0 | J10: 70 | L10: 1
A11: SkeletonCaptain | B11: 4 | C11: 1 | E11: 2 | G11: 1 | H11: 0 | J11: 70 | L11: 2
A12: VampireBat | B12: 1 | C12: 2 | E12: 0 | G12: 2 | H12: 0 | J12: 65 | L12: 1.5
A13: TyrantRex | B13: 5 | C13: 5 | D13: 0 | E13: 3 | F13: 2 | H13: 1.5 | J13: 70 | K13: 3 | L13: 70 | M13: 0

Sheet monster-attributes-per-level
A1: monsterType | B1: Strength | C1: Dexterity | D1: Spirit | E1: Vitality | F1: Agility | G1: Speed | H1: ArmorClass | I1: ArmorPenetration | J1: Accuracy | K1: Evasion | L1: Hp | M1: Mp
A2: Wolf | B2: 7 | C2: 8 | E2: 1.5 | F2: 2 | H2: 4.5 | K2: 10 | L2: 4.5 | M2: 0
A3: FireMage | D3: 10 | E3: 1.5 | F3: 1.5 | H3: 2.5 | K3: 1 | L3: 4.5
A4: Cultist | D4: 14 | F4: 1.5 | K4: 0 | L4: 0
A5: MantaRay | D5: 6 | E5: 1 | F5: 1.5 | L5: 22
A6: Net | G6: 10
A7: Spider | B7: 8 | C7: 6 | E7: 1.5 | F7: 2 | H7: 7.5 | K7: 12 | L7: 4.5 | M7: 0
A8: Slime | B8: 3 | C8: 3 | D8: 2 | E8: 0.5 | F8: 1 | H8: 2 | K8: 6 | L8: 3.5 | M8: 0
A9: Zombie | B9: 5 | C9: 3 | E9: 2.5 | F9: 2 | H9: 4.5 | K9: 2 | L9: 4.5 | M9: 0
A10: SkeletonWarrior | B10: 4 | C10: 4 | E10: 2 | F10: 2 | H10: 7.5 | K10: 2 | L10: 3.5 | M10: 0
A11: SkeletonCaptain | B11: 4 | C11: 5 | D11: 2 | E11: 2 | F11: 2 | H11: 7.5 | K11: 2 | L11: 3.5 | M11: 0
A12: VampireBat | B12: 2 | C12: 5 | D12: 2 | E12: 1 | F12: 3 | H12: 1.5 | K12: 3 | L12: 1.5 | M12: 0
A13: TyrantRex | B13: 5 | C13: 5 | D13: 0 | E13: 3 | F13: 2 | H13: 1.5 | K13: 3 | L13: 3.5 | M13: 0
